<?xml version='1.0'?>

<robot name="robothesis"
  xmlns:xacro="http://www.ros.org/wiki/xacro">

  <xacro:include filename="$(find robothesis)/urdf/robothesis.gazebo" />

  <gazebo reference="left_wheel">
    <material>Gazebo/Green</material>
  </gazebo>

  <gazebo reference="right_wheel">
    <material>Gazebo/Green</material>
  </gazebo>

  <gazebo reference="camera">
    <material>Gazebo/Red</material>
  </gazebo>

  <gazebo reference="chassis">
    <material>Gazebo/Blue</material>
  </gazebo>
  <link name="base_link"></link>

  <joint name="robot_footprint_joint" type="fixed">
    <origin xyz="0 0 0" rpy="0 0 0" />
    <parent link="base_link"/>
    <child link="chassis" />
  </joint>

  <joint name="camera_joint" type="fixed">
    <origin xyz="0.26 0 0" rpy="0 0 0" />
    <parent link="chassis"/>
    <child link="camera" />
    <axis xyz="0 1 0"/>
  </joint>

 <joint name="gps_joint" type="fixed">
        <axis xyz="0 1 0"/>
        <parent link="chassis"/>
        <child link="gps_link"/>
        <origin xyz="0 0 0.14" rpy="0 0 3.14159"/>
    </joint>

    
    <joint name="imu_joint" type="fixed">
    <axis xyz="1 0 0"/> 
    <origin xyz="0 0 0.19"/>
    <parent link="chassis"/>
    <child link="imu_link"/>
  </joint>


  <joint name="hokuyo_joint" type="fixed">
    <origin xyz="0.2 0 0.2" rpy="0 0 0" />
    <parent link="chassis"/>
    <child link="hokuyo" />
    <axis xyz="0 1 0"/>
  </joint>

  <joint type="continuous" name="left_wheel_hinge">
    <origin xyz="0 0.30 0" rpy="0 0 0" />
    <parent link="chassis"/>
    <child link="left_wheel" />
    <axis xyz="0 1 0" rpy="0 0 0" />
    <limit effort="10000" velocity="1000" />
    <dynamics damping="1.0" friction="1.0" />
  </joint>

  <joint type="continuous" name="right_wheel_hinge">
    <origin xyz="0 -0.30 0" rpy="0 0 0" />
    <parent link="chassis"/>
    <child link="right_wheel" />
    <axis xyz="0 1 0" rpy="0 0 0" />
    <limit effort="10000" velocity="1000" />
    <dynamics damping="1.0" friction="1.0" />
  </joint>
  
  <!--Description for Distance sensor 1-->
  <joint name = "ruler_joint1" type = "fixed">
    <axis xyz = "0 1 0" />
    <origin xyz = "0.2 0.15 0.07" rpy = "0 0 0" />
    <parent link = "chassis" /> 
    <child link ="link_1 " /> 
  </joint> 
  <link name ="link_1 ">
    <collision>
      <origin xyz = "-0.05 0 0" rpy = "0 0 0" />
      <geometry> <box size = "0.05 0.05 0.05" />
      </geometry>
    </collision>
   <visual>
     <origin xyz = "0 0 0" rpy = "0 0 0" />
     <geometry>
        <box size = "0.05 0.05 0.05" />
     </geometry>
   </visual>
   <inertial>
    <mass value = "1e-5" />
    <origin xyz = "0 0 0" rpy = "0 0 0" />
    <inertia ixx = "1e-6" ixy = "0" ixz = "0" iyy = "1e-6" iyz = "0" izz = "1e-6" />
   </inertial>
  </link>
  <!--Description for Distance sensor 2-->
  <joint name = "ruler_joint2" type = "fixed">
    <axis xyz = "0 1 0" />
    <origin xyz = "0.2 -0.15 0.07" rpy = "0 0 0" />
    <parent link = "chassis" /> 
    <child link ="link_2" /> 
  </joint> 
  <link name ="link_2">
    <collision>
      <origin xyz = "-0.05 0 0" rpy = "0 0 0" />
      <geometry> 
       <box size = "0.05 0.05 0.05" />
      </geometry>
    </collision>
   <visual>
     <origin xyz = "0 0 0" rpy = "0 0 0" />
     <geometry>
         <box size = "0.05 0.05 0.05" />
     </geometry>
   </visual>
   <inertial>
    <mass value = "1e-5" />
    <origin xyz = "0 0 0" rpy = "0 0 0" />
    <inertia ixx = "1e-6" ixy = "0" ixz = "0" iyy = "1e-6" iyz = "0" izz = "1e-6" />
   </inertial>
  </link>
  <!--Description for Distance sensor 3-->
  <joint name = "ruler_joint3" type = "fixed">
    <axis xyz = "0 1 0" />
    <origin xyz = "0.15 0.15 0.15" rpy = "0 0 0" />
    <parent link = "chassis" /> 
    <child link ="link_3" /> 
  </joint> 
  <link name ="link_3">
    <collision>
      <origin xyz = "-0.05 0 0" rpy = "0 0 0" />
      <geometry> 
         <box size = "0.05 0.05 0.05" />
      </geometry>
    </collision>
   <visual>
     <origin xyz = "0 0 0" rpy = "0 0 0" />
     <geometry>
        <box size = "0.05 0.05 0.05" />
     </geometry>
   </visual>
   <inertial>
    <mass value = "1e-5" />
    <origin xyz = "0 0 0" rpy = "0 0 0" />
    <inertia ixx = "1e-6" ixy = "0" ixz = "0" iyy = "1e-6" iyz = "0" izz = "1e-6" />
   </inertial>
  </link>
  <!--Description for Distance sensor 4-->
  <joint name = "ruler_joint4" type = "fixed">
    <axis xyz = "0 1 0" />
    <origin xyz = "-0.15 0.15 0.15" rpy = "0 0 0" />
    <parent link = "chassis" /> 
    <child link ="link_4" /> 
  </joint> 
  <link name ="link_4">
    <collision>
      <origin xyz = "-0.05 0 0" rpy = "0 0 0" />
      <geometry> 
         <box size = "0.05 0.05 0.05" />
      </geometry>
    </collision>
   <visual>
     <origin xyz = "0 0 0" rpy = "0 0 0" />
     <geometry>
        <box size = "0.05 0.05 0.05" />
     </geometry>
   </visual>
   <inertial>
    <mass value = "1e-5" />
    <origin xyz = "0 0 0" rpy = "0 0 0" />
    <inertia ixx = "1e-6" ixy = "0" ixz = "0" iyy = "1e-6" iyz = "0" izz = "1e-6" />
   </inertial>
  </link>
  
  
  <link name="camera">
    <inertial>
      <mass value="0.1"/>
      <origin xyz="0 0 0" rpy="0 0 0"/>
      <inertia ixx="1e-6" ixy="0.0" ixz="0.0" iyy="1e-6" iyz="0.0" izz="1e-6" />
    </inertial>

    <collision>
      <origin xyz="0 0 0" rpy="0 0 0"/>
      <geometry>
        <box size="0.05 0.05 0.05"/>
      </geometry>
    </collision>

    <visual>
      <origin xyz="0 0 0" rpy="0 0 0"/>
      <geometry>
        <box size="0.05 0.05 0.05"/>
      </geometry>
    </visual>

  </link>

<link name="gps_link">
        <inertial>
            <mass value="0.001"/>
            <origin rpy="0 0 0" xyz="0 0 0"/>
            <inertia ixx="0.0001" ixy="0" ixz="0" iyy="0.000001" iyz="0" izz="0.0001"/>
        </inertial>
        <visual>
            <origin rpy="0 0 0" xyz="0 0 0"/>
            <geometry>
                <mesh filename="package://robothesis/meshes/GPSAntennaScaledDown.dae"/>
            </geometry>
        </visual>
        <collision>
            <origin rpy="0 0 0" xyz="0 0 0"/>
            <geometry>
                <box size="0.096 0.096 0.096"/>
            </geometry>
        </collision>
    </link>
 

<link name="imu_link">
  <inertial>
    <mass value="0.001"/>
    <origin rpy="0 0 0" xyz="0 0 0"/>
    <inertia ixx="0.0001" ixy="0" ixz="0" iyy="0.000001" iyz="0" izz="0.0001"/>
  </inertial>
  <visual>
    <origin rpy="0 0 0" xyz="0 0 0"/>
    <geometry>
      <box size="0.001 0.001 0.001"/>
    </geometry>
  </visual>
  <collision>
    <origin rpy="0 0 0" xyz="0 0 0"/>
    <geometry>
      <box size=".001 .001 .001"/>
    </geometry>
  </collision>
</link>



  <link name="hokuyo">
    <inertial>
      <mass value="1e-5"/>
      <origin xyz="0 0 0" rpy="0 0 0"/>
      <inertia ixx="1e-6" ixy="0.0" ixz="0.0" iyy="1e-6" iyz="0.0" izz="1e-6" />
    </inertial>

    <collision>
      <origin xyz="0 0 0" rpy="0 0 0"/>
      <geometry>
        <box size="0.1 0.1 0.1"/>
      </geometry>
    </collision>

    <visual>
      <origin xyz="0 0 0" rpy="0 0 0"/>
      <geometry>
        <mesh filename="package://robothesis/meshes/hokuyo.dae"/>
      </geometry>
    </visual>

  </link>

  <link name="left_wheel">
    <inertial>
      <mass value="5"/>
      <origin xyz="0 0 0" rpy="0 1.5707 1.5707"/>
      <inertia ixx="0.1" ixy="0.0" ixz="0.0" iyy="0.1" iyz="0.0" izz="0.1" />
    </inertial>

    <collision>
      <origin xyz="0 0 0" rpy="0 1.5707 1.5707"/>
      <geometry>
        <cylinder radius="0.1" length="0.05"/>
      </geometry>
    </collision>

    <visual>
      <origin xyz="0 0 0" rpy="0 1.5707 1.5707"/>
      <geometry>
        <cylinder radius="0.1" length="0.05"/>
      </geometry>
    </visual>

  </link>

  <link name="right_wheel">
    <inertial>
      <mass value="5"/>
      <origin xyz="0 0 0" rpy="0 1.5707 1.5707"/>
      <inertia ixx="0.1" ixy="0.0" ixz="0.0" iyy="0.1" iyz="0.0" izz="0.1" />
    </inertial>

    <collision>
      <origin xyz="0 0 0" rpy="0 1.5707 1.5707"/>
      <geometry>
        <cylinder radius="0.1" length="0.05"/>
      </geometry>
    </collision>

    <visual>
      <origin xyz="0 0 0" rpy="0 1.5707 1.5707"/>
      <geometry>
        <cylinder radius="0.1" length="0.05"/>
      </geometry>
    </visual>

  </link>

  <link name='chassis'>
    <pose>0 0 0.1 0 0 0</pose>

    <inertial>
      <mass value="15.0"/>
      <origin xyz="0.0 0 0" rpy=" 0 0 0"/>
      <inertia ixx="0.1" ixy="0" ixz="0" iyy="0.1" iyz="0" izz="0.1" />
    </inertial>

    <collision name='collision'>
      <origin xyz="0 0 0.05" rpy=" 0 0 0"/>
      <geometry>
        <cylinder length="0.2" radius="0.25"/>
      </geometry>
    </collision>

    <visual name='chassis_visual'>
      <origin xyz="0 0 0.05" rpy=" 0 0 0"/>
      <geometry>
        <cylinder length="0.2" radius="0.25"/>
      </geometry>
    </visual>


    <collision name='back_caster_collision'>
      <origin xyz="-0.15 0 -0.05" rpy=" 0 0 0"/>
      <geometry>
        <sphere radius="0.0499"/>
      </geometry>
    </collision>

    <visual name='back_caster_visual'>
      <origin xyz="-0.15 0 -0.05" rpy=" 0 0 0"/>
      <geometry>
        <sphere radius="0.05"/>
      </geometry>
    </visual>

    <collision name='front_caster_collision'>
      <origin xyz="0.15 0 -0.05" rpy=" 0 0 0"/>
      <geometry>
        <sphere radius="0.0499"/>
      </geometry>
    </collision>

    <visual name='front_caster_visual'>
      <origin xyz="0.15 0 -0.05" rpy=" 0 0 0"/>
      <geometry>
        <sphere radius="0.05"/>
      </geometry>
    </visual>

  </link>

</robot>
